Workbook

Sheet Cronograma (Gantt)
A1: Cronograma del proyecto GASTRO-SIM – Diagrama de Gantt
A2: Línea base v1.0 · 11/10/2026 · Equipo ITEVOLUTION · Calendario de 7 días · Dedicación supuesta: 3 h por persona y día (≈ 21 h/semana) · Fuente: EDT v1.0, Matriz de Trazabilidad v1.3 y MoSCoW v1.3
A3: Barras: azul = actividad; gris = fase; ◆ = hito (duración 0). Celdas amarillas: % completado (actualizar cada semana).
O5: oct | AR5: nov
A6: ID | B6: EDT | C6: Actividad / hito | D6: Tipo | E6: Responsable | F6: Ejecuta | G6: Esfuerzo (h) | H6: Duración (días) | I6: Inicio | J6: Fin | K6: Predecesoras | L6: Ciclo | M6: Prioridad | N6: % completado | O6: 46298 | P6: 46299 | Q6: 46300 | R6: 46301 | S6: 46302 | T6: 46303 | U6: 46304 | V6: 46305 | W6: 46306 | X6: 46307 | Y6: 46308 | Z6: 46309 | AA6: 46310 | AB6: 46311 | AC6: 46312 | AD6: 46313 | AE6: 46314 | AF6: 46315 | AG6: 46316 | AH6: 46317 | AI6: 46318 | AJ6: 46319 | AK6: 46320 | AL6: 46321 | AM6: 46322 | AN6: 46323 | AO6: 46324 | AP6: 46325 | AQ6: 46326 | AR6: 46327 | AS6: 46328 | AT6: 46329 | AU6: 46330 | AV6: 46331 | AW6: 46332 | AX6: 46333 | AY6: 46334 | AZ6: 46335 | BA6: 46336 | BB6: 46337 | BC6: 46338 | BD6: 46339 | BE6: 46340 | BF6: 46341 | BG6: 46342 | BH6: 46343 | BI6: 46344 | BJ6: 46345 | BK6: 46346 | BL6: 46347 | BM6: 46348 | BN6: 46349 | BO6: 46350 | BP6: 46351 | BQ6: 46352 | BR6: 46353 | BS6: 46354 | BT6: 46355
C7: HITOS DEL PROYECTO | D7: Fase | H7: =IF(D7="Hito",0,J7-I7+1) | I7: =MIN(I8:I20) | J7: =MAX(J8:J20)
A8: H01 | C8: Proyecto iniciado: equipo y roles definidos | D8: Hito | E8: Emmanuel Ospina | G8: 0 | H8: =IF(D8="Hito",0,J8-I8+1) | I8: 46298 | J8: 46298 | M8: Obligatorio | N8: 1 | O8: =IF(O$6=$I8,"◆","") | P8: =IF(P$6=$I8,"◆","") | Q8: =IF(Q$6=$I8,"◆","") | R8: =IF(R$6=$I8,"◆","") | S8: =IF(S$6=$I8,"◆","") | T8: =IF(T$6=$I8,"◆","") | U8: =IF(U$6=$I8,"◆","") | V8: =IF(V$6=$I8,"◆","") | ... BT8: =IF(BT$6=$I8,"◆","")
A9: H02 | C9: Acta de Constitución y Matriz de Partes Interesadas entregadas | D9: Hito | E9: Emmanuel Ospina | G9: 0 | H9: =IF(D9="Hito",0,J9-I9+1) | I9: 46301 | J9: 46301 | K9: 1101, 1102 | M9: Obligatorio | N9: 1 | O9: =IF(O$6=$I9,"◆","") | P9: =IF(P$6=$I9,"◆","") | Q9: =IF(Q$6=$I9,"◆","") | R9: =IF(R$6=$I9,"◆","") | S9: =IF(S$6=$I9,"◆","") | T9: =IF(T$6=$I9,"◆","") | U9: =IF(U$6=$I9,"◆","") | V9: =IF(V$6=$I9,"◆","") | ... BT9: =IF(BT$6=$I9,"◆","")
A10: H03 | C10: Requisitos aprobados por el Propietario del Proyecto | D10: Hito | E10: Emmanuel Ospina | G10: 0 | H10: =IF(D10="Hito",0,J10-I10+1) | I10: 46306 | J10: 46306 | K10: 2101, 2201, 2301 | M10: Obligatorio | N10: 1 | O10: =IF(O$6=$I10,"◆","") | P10: =IF(P$6=$I10,"◆","") | Q10: =IF(Q$6=$I10,"◆","") | R10: =IF(R$6=$I10,"◆","") | S10: =IF(S$6=$I10,"◆","") | T10: =IF(T$6=$I10,"◆","") | U10: =IF(U$6=$I10,"◆","") | V10: =IF(V$6=$I10,"◆","") | ... BT10: =IF(BT$6=$I10,"◆","")
A11: H04 | C11: Línea base del alcance y del cronograma establecida (v0.1) | D11: Hito | E11: Emmanuel Ospina | G11: 0 | H11: =IF(D11="Hito",0,J11-I11+1) | I11: 46306 | J11: 46306 | K11: 1201, 1202, 1203, 1303 | M11: Obligatorio | N11: 1 | O11: =IF(O$6=$I11,"◆","") | P11: =IF(P$6=$I11,"◆","") | Q11: =IF(Q$6=$I11,"◆","") | R11: =IF(R$6=$I11,"◆","") | S11: =IF(S$6=$I11,"◆","") | T11: =IF(T$6=$I11,"◆","") | U11: =IF(U$6=$I11,"◆","") | V11: =IF(V$6=$I11,"◆","") | ... BT11: =IF(BT$6=$I11,"◆","")
A12: H05 | C12: Plan de gestión de la calidad entregado | D12: Hito | E12: Emmanuel Ospina | G12: 0 | H12: =IF(D12="Hito",0,J12-I12+1) | I12: 46313 | J12: 46313 | K12: 1204 | M12: Obligatorio | N12: 0 | O12: =IF(O$6=$I12,"◆","") | P12: =IF(P$6=$I12,"◆","") | Q12: =IF(Q$6=$I12,"◆","") | R12: =IF(R$6=$I12,"◆","") | S12: =IF(S$6=$I12,"◆","") | T12: =IF(T$6=$I12,"◆","") | U12: =IF(U$6=$I12,"◆","") | V12: =IF(V$6=$I12,"◆","") | ... BT12: =IF(BT$6=$I12,"◆","")
A13: H06 | C13: Prototipo técnico 3D validado | D13: Hito | E13: Emmanuel Ospina | G13: 0 | H13: =IF(D13="Hito",0,J13-I13+1) | I13: 46316 | J13: 46316 | K13: 3501 | M13: Opcional | N13: 0 | O13: =IF(O$6=$I13,"◆","") | P13: =IF(P$6=$I13,"◆","") | Q13: =IF(Q$6=$I13,"◆","") | R13: =IF(R$6=$I13,"◆","") | S13: =IF(S$6=$I13,"◆","") | T13: =IF(T$6=$I13,"◆","") | U13: =IF(U$6=$I13,"◆","") | V13: =IF(V$6=$I13,"◆","") | ... BT13: =IF(BT$6=$I13,"◆","")
A14: H07 | C14: Diseño del software completo | D14: Hito | E14: Emmanuel Ospina | G14: 0 | H14: =IF(D14="Hito",0,J14-I14+1) | I14: 46316 | J14: 46316 | K14: 3101, 3201, 3301, 3401, 3501 | M14: Obligatorio | N14: 0 | O14: =IF(O$6=$I14,"◆","") | P14: =IF(P$6=$I14,"◆","") | Q14: =IF(Q$6=$I14,"◆","") | R14: =IF(R$6=$I14,"◆","") | S14: =IF(S$6=$I14,"◆","") | T14: =IF(T$6=$I14,"◆","") | U14: =IF(U$6=$I14,"◆","") | V14: =IF(V$6=$I14,"◆","") | ... BT14: =IF(BT$6=$I14,"◆","")
A15: H08 | C15: Versión v0.5 aceptada (fin del ciclo TSP 1) | D15: Hito | E15: Emmanuel Ospina | G15: 0 | H15: =IF(D15="Hito",0,J15-I15+1) | I15: 46320 | J15: 46320 | K15: 4612, 4304, 4601, 4205, 4602, 4605… | M15: Obligatorio | N15: 0 | O15: =IF(O$6=$I15,"◆","") | P15: =IF(P$6=$I15,"◆","") | Q15: =IF(Q$6=$I15,"◆","") | R15: =IF(R$6=$I15,"◆","") | S15: =IF(S$6=$I15,"◆","") | T15: =IF(T$6=$I15,"◆","") | U15: =IF(U$6=$I15,"◆","") | V15: =IF(V$6=$I15,"◆","") | ... BT15: =IF(BT$6=$I15,"◆","")
A16: H09 | C16: Primer caso clínico generado por la IA de extremo a extremo | D16: Hito | E16: Emmanuel Ospina | G16: 0 | H16: =IF(D16="Hito",0,J16-I16+1) | I16: 46334 | J16: 46334 | K16: 4208, 4104 | M16: Opcional | N16: 0 | O16: =IF(O$6=$I16,"◆","") | P16: =IF(P$6=$I16,"◆","") | Q16: =IF(Q$6=$I16,"◆","") | R16: =IF(R$6=$I16,"◆","") | S16: =IF(S$6=$I16,"◆","") | T16: =IF(T$6=$I16,"◆","") | U16: =IF(U$6=$I16,"◆","") | V16: =IF(V$6=$I16,"◆","") | ... BT16: =IF(BT$6=$I16,"◆","")
A17: H10 | C17: Versión v0.9 aceptada (flujo completo integrado) | D17: Hito | E17: Emmanuel Ospina | G17: 0 | H17: =IF(D17="Hito",0,J17-I17+1) | I17: 46341 | J17: 46341 | K17: 4101, 4204, 4207, 4610, 4208, 4501… | M17: Obligatorio | N17: 0 | O17: =IF(O$6=$I17,"◆","") | P17: =IF(P$6=$I17,"◆","") | Q17: =IF(Q$6=$I17,"◆","") | R17: =IF(R$6=$I17,"◆","") | S17: =IF(S$6=$I17,"◆","") | T17: =IF(T$6=$I17,"◆","") | U17: =IF(U$6=$I17,"◆","") | V17: =IF(V$6=$I17,"◆","") | ... BT17: =IF(BT$6=$I17,"◆","")
A18: H11 | C18: Pruebas del software completadas | D18: Hito | E18: Emmanuel Ospina | G18: 0 | H18: =IF(D18="Hito",0,J18-I18+1) | I18: 46348 | J18: 46348 | K18: 5101, 5201, 5301, 5401 | M18: Obligatorio | N18: 0 | O18: =IF(O$6=$I18,"◆","") | P18: =IF(P$6=$I18,"◆","") | Q18: =IF(Q$6=$I18,"◆","") | R18: =IF(R$6=$I18,"◆","") | S18: =IF(S$6=$I18,"◆","") | T18: =IF(T$6=$I18,"◆","") | U18: =IF(U$6=$I18,"◆","") | V18: =IF(V$6=$I18,"◆","") | ... BT18: =IF(BT$6=$I18,"◆","")
A19: H12 | C19: Versión 1.0 aceptada y demostración realizada | D19: Hito | E19: Emmanuel Ospina | G19: 0 | H19: =IF(D19="Hito",0,J19-I19+1) | I19: 46355 | J19: 46355 | K19: 1404, 1402 | M19: Obligatorio | N19: 0 | O19: =IF(O$6=$I19,"◆","") | P19: =IF(P$6=$I19,"◆","") | Q19: =IF(Q$6=$I19,"◆","") | R19: =IF(R$6=$I19,"◆","") | S19: =IF(S$6=$I19,"◆","") | T19: =IF(T$6=$I19,"◆","") | U19: =IF(U$6=$I19,"◆","") | V19: =IF(V$6=$I19,"◆","") | ... BT19: =IF(BT$6=$I19,"◆","")
A20: H13 | C20: Proyecto cerrado | D20: Hito | E20: Emmanuel Ospina | G20: 0 | H20: =IF(D20="Hito",0,J20-I20+1) | I20: 46355 | J20: 46355 | K20: 1403, 1401 | M20: Obligatorio | N20: 0 | O20: =IF(O$6=$I20,"◆","") | P20: =IF(P$6=$I20,"◆","") | Q20: =IF(Q$6=$I20,"◆","") | R20: =IF(R$6=$I20,"◆","") | S20: =IF(S$6=$I20,"◆","") | T20: =IF(T$6=$I20,"◆","") | U20: =IF(U$6=$I20,"◆","") | V20: =IF(V$6=$I20,"◆","") | ... BT20: =IF(BT$6=$I20,"◆","")
C21: INICIO | D21: Fase | G21: =SUM(G22:G23) | H21: =IF(D21="Hito",0,J21-I21+1) | I21: =MIN(I22:I23) | J21: =MAX(J22:J23) | N21: =IFERROR(SUMPRODUCT(G22:G23,N22:N23)/SUM(G22:G23),0)
A22: 1101 | B22: 1.1.1 | C22: Elaborar el Acta de Constitución del Proyecto | D22: Actividad | E22: Emmanuel Ospina | F22: Emmanuel Ospina | G22: 8 | H22: =IF(D22="Hito",0,J22-I22+1) | I22: 46298 | J22: 46300 | L22: Inicio | M22: — | N22: 1
A23: 1102 | B23: 1.1.2 | C23: Elaborar la Matriz de Partes Interesadas | D23: Actividad | E23: Emmanuel Ospina | F23: Emmanuel Ospina | G23: 4 | H23: =IF(D23="Hito",0,J23-I23+1) | I23: 46299 | J23: 46300 | L23: Inicio | M23: — | N23: 1
C24: ANÁLISIS | D24: Fase | G24: =SUM(G25:G27) | H24: =IF(D24="Hito",0,J24-I24+1) | I24: =MIN(I25:I27) | J24: =MAX(J25:J27) | N24: =IFERROR(SUMPRODUCT(G25:G27,N25:N27)/SUM(G25:G27),0)
A25: 2101 | B25: 2.1 | C25: Especificar los requisitos y su trazabilidad | D25: Actividad | E25: Jahan Chará | F25: Jahan Chará | G25: 14 | H25: =IF(D25="Hito",0,J25-I25+1) | I25: 46300 | J25: 46306 | L25: Análisis | M25: — | N25: 1
A26: 2201 | B26: 2.2 | C26: Modelar el diagrama de casos de uso | D26: Actividad | E26: Jahan Chará | F26: Jahan Chará | G26: 6 | H26: =IF(D26="Hito",0,J26-I26+1) | I26: 46300 | J26: 46306 | L26: Análisis | M26: — | N26: 1
A27: 2301 | B27: 2.3 | C27: Priorizar los requisitos con MoSCoW | D27: Actividad | E27: Emmanuel Ospina | F27: Emmanuel Ospina | G27: 4 | H27: =IF(D27="Hito",0,J27-I27+1) | I27: 46300 | J27: 46306 | L27: Análisis | M27: — | N27: 1
C28: PLANEACIÓN | D28: Fase | G28: =SUM(G29:G34) | H28: =IF(D28="Hito",0,J28-I28+1) | I28: =MIN(I29:I34) | J28: =MAX(J29:J34) | N28: =IFERROR(SUMPRODUCT(G29:G34,N29:N34)/SUM(G29:G34),0)
A29: 1201 | B29: 1.2.1 | C29: Elaborar el Plan de Gestión del Alcance | D29: Actividad | E29: Emmanuel Ospina | F29: Emmanuel Ospina | G29: 6 | H29: =IF(D29="Hito",0,J29-I29+1) | I29: 46306 | J29: 46306 | K29: H03 | L29: Planeación | M29: — | N29: 1
A30: 1202 | B30: 1.2.2 | C30: Crear la EDT y su diccionario | D30: Actividad | E30: Jahan Chará | F30: Jahan Chará | G30: 6 | H30: =IF(D30="Hito",0,J30-I30+1) | I30: 46306 | J30: 46306 | K30: H03 | L30: Planeación | M30: — | N30: 1
A31: 1203 | B31: 1.2.3 | C31: Elaborar el plan de cronograma, la lista de actividades y la lista de hitos | D31: Actividad | E31: Jahan Chará | F31: Jahan Chará | G31: 8 | H31: =IF(D31="Hito",0,J31-I31+1) | I31: 46306 | J31: 46306 | K31: 1202 | L31: Planeación | M31: — | N31: 1
A32: 1303 | B32: 1.3.2 | C32: Configurar el repositorio y el tablero del proyecto | D32: Actividad | E32: Cristian Cruz | F32: Cristian Cruz | G32: 4 | H32: =IF(D32="Hito",0,J32-I32+1) | I32: 46306 | J32: 46306 | K32: 1202 | L32: Planeación | M32: — | N32: 1
A33: 1204 | B33: 1.2.4 | C33: Elaborar el Plan de Gestión de la Calidad | D33: Actividad | E33: Nestor Velasco | F33: Nestor Velasco | G33: 6 | H33: =IF(D33="Hito",0,J33-I33+1) | I33: 46307 | J33: 46308 | K33: H04 | L33: Planeación | M33: — | N33: 0
A34: 1304 | B34: 1.3.3 | C34: Elaborar el plan de pruebas y calidad del software | D34: Actividad | E34: Nestor Velasco | F34: Nestor Velasco | G34: 3 | H34: =IF(D34="Hito",0,J34-I34+1) | I34: 46309 | J34: 46309 | K34: 1204 | L34: Planeación | M34: — | N34: 0
C35: MONITOREO Y CONTROL | D35: Fase | G35: =SUM(G36:G37) | H35: =IF(D35="Hito",0,J35-I35+1) | I35: =MIN(I36:I37) | J35: =MAX(J36:J37) | N35: =IFERROR(SUMPRODUCT(G36:G37,N36:N37)/SUM(G36:G37),0)
A36: 1301 | B36: 1.3.1 | C36: Realizar el seguimiento semanal TSP | D36: Actividad | E36: Emmanuel Ospina | F36: Emmanuel Ospina | G36: 14 | H36: =IF(D36="Hito",0,J36-I36+1) | I36: 46307 | J36: 46355 | K36: H04 | L36: Continuo | M36: — | N36: 0
A37: 1302 | B37: 1.3.2 | C37: Controlar los cambios del alcance y del cronograma | D37: Actividad | E37: Emmanuel Ospina | F37: Emmanuel Ospina | G37: 3 | H37: =IF(D37="Hito",0,J37-I37+1) | I37: 46307 | J37: 46355 | K37: H04 | L37: Continuo | M37: — | N37: 0
C38: DISEÑO | D38: Fase | G38: =SUM(G39:G43) | H38: =IF(D38="Hito",0,J38-I38+1) | I38: =MIN(I39:I43) | J38: =MAX(J39:J43) | N38: =IFERROR(SUMPRODUCT(G39:G43,N39:N43)/SUM(G39:G43),0)
A39: 3101 | B39: 3.1 | C39: Diseñar la arquitectura y el despliegue | D39: Actividad | E39: Diego Agudelo | F39: Diego Agudelo | G39: 8 | H39: =IF(D39="Hito",0,J39-I39+1) | I39: 46307 | J39: 46309 | K39: H04 | L39: Diseño | M39: — | N39: 0
A40: 3201 | B40: 3.2 | C40: Elaborar los diagramas UML de diseño | D40: Actividad | E40: Jahan Chará | F40: Jahan Chará | G40: 10 | H40: =IF(D40="Hito",0,J40-I40+1) | I40: 46307 | J40: 46310 | K40: H04 | L40: Diseño | M40: — | N40: 0
A41: 3401 | B41: 3.4 | C41: Diseñar los prototipos de interfaz | D41: Actividad | E41: Cristian Cruz | F41: Cristian Cruz | G41: 10 | H41: =IF(D41="Hito",0,J41-I41+1) | I41: 46307 | J41: 46310 | K41: H04 | L41: Diseño | M41: — | N41: 0
...

Sheet Lista de hitos
A1: Lista de hitos – GASTRO-SIM
A3: N.º | B3: Hito | C3: Obligatorio / opcional | D3: Fecha objetivo | E3: Verificación (evidencia) | F3: Se cumple cuando terminan | G3: Hito del Acta
A4: 001 | B4: Proyecto iniciado: equipo y roles definidos | C4: Obligatorio | D4: 46298 | E4: Registro del equipo ITEVOLUTION y de los roles en Moodle (archivo «Grupo y roles»). | G4: —
A5: 002 | B5: Acta de Constitución y Matriz de Partes Interesadas entregadas | C5: Obligatorio | D5: 46301 | E5: Entrega en Moodle y visto bueno del Propietario del Proyecto. | F5: 1101, 1102 | G5: H1
A6: 003 | B6: Requisitos aprobados por el Propietario del Proyecto | C6: Obligatorio | D6: 46306 | E6: Correo de retroalimentación del Propietario con visto bueno («podrán construir el plan del alcance») y versión v1.3 de los artefactos. | F6: 2101, 2201, 2301 | G6: H2
A7: 004 | B7: Línea base del alcance y del cronograma establecida (v0.1) | C7: Obligatorio | D7: 46306 | E7: Plan de alcance, EDT, plan de cronograma, lista de actividades y lista de hitos entregados en Moodle; etiqueta v0.1 en GitHub. | F7: 1201, 1202, 1203, 1303 | G7: H3
A8: 005 | B8: Plan de gestión de la calidad entregado | C8: Obligatorio | D8: 46313 | E8: Entrega en Moodle y revisión del Propietario. | F8: 1204 | G8: —
A9: 006 | B9: Prototipo técnico 3D validado | C9: Opcional | D9: 46316 | E9: Demostración interna en la reunión TSP: cámara que recorre la ruta y captura un hallazgo de prueba. | F9: 3501 | G9: —
A10: 007 | B10: Diseño del software completo | C10: Obligatorio | D10: 46316 | E10: Documento de diseño revisado por el Proveedor de Soluciones y publicado en el repositorio. | F10: 3101, 3201, 3301, 3401, 3501 | G10: —
A11: 008 | B11: Versión v0.5 aceptada (fin del ciclo TSP 1) | C11: Obligatorio | D11: 46320 | E11: Release v0.5 en GitHub, acta de aceptación firmada por el Propietario y postmortem del ciclo 1. | F11: 4612, 4304, 4601, 4205, 4602, 4605, 4206, 4201… | G11: H4
A12: 009 | B12: Primer caso clínico generado por la IA de extremo a extremo | C12: Opcional | D12: 46334 | E12: Demostración interna: un caso generado, validado y mostrado en la escena 3D. | F12: 4208, 4104 | G12: —
A13: 010 | B13: Versión v0.9 aceptada (flujo completo integrado) | C13: Obligatorio | D13: 46341 | E13: Release v0.9 en GitHub, acta de aceptación del Propietario y postmortem del ciclo 2. | F13: 4101, 4204, 4207, 4610, 4208, 4501, 4102, 4301… | G13: H5
A14: 011 | B14: Pruebas del software completadas | C14: Obligatorio | D14: 46348 | E14: Reporte de pruebas funcionales, de rendimiento y de usabilidad (SUS ≥ 68) aprobado por el Tester. | F14: 5101, 5201, 5301, 5401 | G14: H6
A15: 012 | B15: Versión 1.0 aceptada y demostración realizada | C15: Obligatorio | D15: 46355 | E15: Release v1.0 con Docker y README, demostración al Propietario y acta de aceptación final. | F15: 1404, 1402 | G15: H7
A16: 013 | B16: Proyecto cerrado | C16: Obligatorio | D16: 46355 | E16: Acta de cierre firmada, lecciones aprendidas e informe final entregados en Moodle. | F16: 1403, 1401 | G16: H7

Sheet Carga por persona
A1: Carga de trabajo por persona y semana (horas)
A2: Calculada con fórmulas a partir de la hoja «Cronograma (Gantt)»: el esfuerzo de cada actividad se reparte por igual entre sus días. Rojo: más de la dedicación supuesta.
A3: Dedicación semanal supuesta (h): | E3: 21
A5: Persona | B5: Semana 1 12/10–18/10 | C5: Semana 2 19/10–25/10 | D5: Semana 3 26/10–01/11 | E5: Semana 4 02/11–08/11 | F5: Semana 5 09/11–15/11 | G5: Semana 6 16/11–22/11 | H5: Semana 7 23/11–29/11 | I5: Total (h) | J5: Promedio h/semana
A6: Emmanuel Ospina | B6: =SUMIF($B$31:$B$108,$A6,C$31:C$108) | C6: =SUMIF($B$31:$B$108,$A6,D$31:D$108) | D6: =SUMIF($B$31:$B$108,$A6,E$31:E$108) | E6: =SUMIF($B$31:$B$108,$A6,F$31:F$108) | F6: =SUMIF($B$31:$B$108,$A6,G$31:G$108) | G6: =SUMIF($B$31:$B$108,$A6,H$31:H$108) | H6: =SUMIF($B$31:$B$108,$A6,I$31:I$108) | I6: =SUM(B6:H6) | J6: =AVERAGE(B6:H6)
A7: Jahan Chará | B7: =SUMIF($B$31:$B$108,$A7,C$31:C$108) | C7: =SUMIF($B$31:$B$108,$A7,D$31:D$108) | D7: =SUMIF($B$31:$B$108,$A7,E$31:E$108) | E7: =SUMIF($B$31:$B$108,$A7,F$31:F$108) | F7: =SUMIF($B$31:$B$108,$A7,G$31:G$108) | G7: =SUMIF($B$31:$B$108,$A7,H$31:H$108) | H7: =SUMIF($B$31:$B$108,$A7,I$31:I$108) | I7: =SUM(B7:H7) | J7: =AVERAGE(B7:H7)
A8: Diego Agudelo | B8: =SUMIF($B$31:$B$108,$A8,C$31:C$108) | C8: =SUMIF($B$31:$B$108,$A8,D$31:D$108) | D8: =SUMIF($B$31:$B$108,$A8,E$31:E$108) | E8: =SUMIF($B$31:$B$108,$A8,F$31:F$108) | F8: =SUMIF($B$31:$B$108,$A8,G$31:G$108) | G8: =SUMIF($B$31:$B$108,$A8,H$31:H$108) | H8: =SUMIF($B$31:$B$108,$A8,I$31:I$108) | I8: =SUM(B8:H8) | J8: =AVERAGE(B8:H8)
A9: Nestor Velasco | B9: =SUMIF($B$31:$B$108,$A9,C$31:C$108) | C9: =SUMIF($B$31:$B$108,$A9,D$31:D$108) | D9: =SUMIF($B$31:$B$108,$A9,E$31:E$108) | E9: =SUMIF($B$31:$B$108,$A9,F$31:F$108) | F9: =SUMIF($B$31:$B$108,$A9,G$31:G$108) | G9: =SUMIF($B$31:$B$108,$A9,H$31:H$108) | H9: =SUMIF($B$31:$B$108,$A9,I$31:I$108) | I9: =SUM(B9:H9) | J9: =AVERAGE(B9:H9)
A10: Cristian Cruz | B10: =SUMIF($B$31:$B$108,$A10,C$31:C$108) | C10: =SUMIF($B$31:$B$108,$A10,D$31:D$108) | D10: =SUMIF($B$31:$B$108,$A10,E$31:E$108) | E10: =SUMIF($B$31:$B$108,$A10,F$31:F$108) | F10: =SUMIF($B$31:$B$108,$A10,G$31:G$108) | G10: =SUMIF($B$31:$B$108,$A10,H$31:H$108) | H10: =SUMIF($B$31:$B$108,$A10,I$31:I$108) | I10: =SUM(B10:H10) | J10: =AVERAGE(B10:H10)
A11: Equipo | B11: =SUM(B6:B10) | C11: =SUM(C6:C10) | D11: =SUM(D6:D10) | E11: =SUM(E6:E10) | F11: =SUM(F6:F10) | G11: =SUM(G6:G10) | H11: =SUM(H6:H10) | I11: =SUM(I6:I10)
A13: Comparación con el Acta: el Acta supuso cerca de 8 h por persona y semana. Esta tabla muestra la dedicación que exige el cronograma con todo el alcance (Must + Should).
C28: 46307 | D28: 46314 | E28: 46321 | F28: 46328 | G28: 46335 | H28: 46342 | I28: 46349
A29: Tabla auxiliar: horas de cada actividad por semana
A30: Fila Gantt | B30: Ejecuta | C30: 46313 | D30: 46320 | E30: 46327 | F30: 46334 | G30: 46341 | H30: 46348 | I30: 46355
A31: 22 | B31: ='Cronograma (Gantt)'!F22 | C31: =MAX(0,MIN('Cronograma (Gantt)'!$J22,C$30)-MAX('Cronograma (Gantt)'!$I22,C$28)+1)*'Cronograma (Gantt)'!$G22/'Cronograma (Gantt)'!$H22 | D31: =MAX(0,MIN('Cronograma (Gantt)'!$J22,D$30)-MAX('Cronograma (Gantt)'!$I22,D$28)+1)*'Cronograma (Gantt)'!$G22/'Cronograma (Gantt)'!$H22 | E31: =MAX(0,MIN('Cronograma (Gantt)'!$J22,E$30)-MAX('Cronograma (Gantt)'!$I22,E$28)+1)*'Cronograma (Gantt)'!$G22/'Cronograma (Gantt)'!$H22 | F31: =MAX(0,MIN('Cronograma (Gantt)'!$J22,F$30)-MAX('Cronograma (Gantt)'!$I22,F$28)+1)*'Cronograma (Gantt)'!$G22/'Cronograma (Gantt)'!$H22 | G31: =MAX(0,MIN('Cronograma (Gantt)'!$J22,G$30)-MAX('Cronograma (Gantt)'!$I22,G$28)+1)*'Cronograma (Gantt)'!$G22/'Cronograma (Gantt)'!$H22 | H31: =MAX(0,MIN('Cronograma (Gantt)'!$J22,H$30)-MAX('Cronograma (Gantt)'!$I22,H$28)+1)*'Cronograma (Gantt)'!$G22/'Cronograma (Gantt)'!$H22 | I31: =MAX(0,MIN('Cronograma (Gantt)'!$J22,I$30)-MAX('Cronograma (Gantt)'!$I22,I$28)+1)*'Cronograma (Gantt)'!$G22/'Cronograma (Gantt)'!$H22
A32: 23 | B32: ='Cronograma (Gantt)'!F23 | C32: =MAX(0,MIN('Cronograma (Gantt)'!$J23,C$30)-MAX('Cronograma (Gantt)'!$I23,C$28)+1)*'Cronograma (Gantt)'!$G23/'Cronograma (Gantt)'!$H23 | D32: =MAX(0,MIN('Cronograma (Gantt)'!$J23,D$30)-MAX('Cronograma (Gantt)'!$I23,D$28)+1)*'Cronograma (Gantt)'!$G23/'Cronograma (Gantt)'!$H23 | E32: =MAX(0,MIN('Cronograma (Gantt)'!$J23,E$30)-MAX('Cronograma (Gantt)'!$I23,E$28)+1)*'Cronograma (Gantt)'!$G23/'Cronograma (Gantt)'!$H23 | F32: =MAX(0,MIN('Cronograma (Gantt)'!$J23,F$30)-MAX('Cronograma (Gantt)'!$I23,F$28)+1)*'Cronograma (Gantt)'!$G23/'Cronograma (Gantt)'!$H23 | G32: =MAX(0,MIN('Cronograma (Gantt)'!$J23,G$30)-MAX('Cronograma (Gantt)'!$I23,G$28)+1)*'Cronograma (Gantt)'!$G23/'Cronograma (Gantt)'!$H23 | H32: =MAX(0,MIN('Cronograma (Gantt)'!$J23,H$30)-MAX('Cronograma (Gantt)'!$I23,H$28)+1)*'Cronograma (Gantt)'!$G23/'Cronograma (Gantt)'!$H23 | I32: =MAX(0,MIN('Cronograma (Gantt)'!$J23,I$30)-MAX('Cronograma (Gantt)'!$I23,I$28)+1)*'Cronograma (Gantt)'!$G23/'Cronograma (Gantt)'!$H23
A33: 25 | B33: ='Cronograma (Gantt)'!F25 | C33: =MAX(0,MIN('Cronograma (Gantt)'!$J25,C$30)-MAX('Cronograma (Gantt)'!$I25,C$28)+1)*'Cronograma (Gantt)'!$G25/'Cronograma (Gantt)'!$H25 | D33: =MAX(0,MIN('Cronograma (Gantt)'!$J25,D$30)-MAX('Cronograma (Gantt)'!$I25,D$28)+1)*'Cronograma (Gantt)'!$G25/'Cronograma (Gantt)'!$H25 | E33: =MAX(0,MIN('Cronograma (Gantt)'!$J25,E$30)-MAX('Cronograma (Gantt)'!$I25,E$28)+1)*'Cronograma (Gantt)'!$G25/'Cronograma (Gantt)'!$H25 | F33: =MAX(0,MIN('Cronograma (Gantt)'!$J25,F$30)-MAX('Cronograma (Gantt)'!$I25,F$28)+1)*'Cronograma (Gantt)'!$G25/'Cronograma (Gantt)'!$H25 | G33: =MAX(0,MIN('Cronograma (Gantt)'!$J25,G$30)-MAX('Cronograma (Gantt)'!$I25,G$28)+1)*'Cronograma (Gantt)'!$G25/'Cronograma (Gantt)'!$H25 | H33: =MAX(0,MIN('Cronograma (Gantt)'!$J25,H$30)-MAX('Cronograma (Gantt)'!$I25,H$28)+1)*'Cronograma (Gantt)'!$G25/'Cronograma (Gantt)'!$H25 | I33: =MAX(0,MIN('Cronograma (Gantt)'!$J25,I$30)-MAX('Cronograma (Gantt)'!$I25,I$28)+1)*'Cronograma (Gantt)'!$G25/'Cronograma (Gantt)'!$H25
A34: 26 | B34: ='Cronograma (Gantt)'!F26 | C34: =MAX(0,MIN('Cronograma (Gantt)'!$J26,C$30)-MAX('Cronograma (Gantt)'!$I26,C$28)+1)*'Cronograma (Gantt)'!$G26/'Cronograma (Gantt)'!$H26 | D34: =MAX(0,MIN('Cronograma (Gantt)'!$J26,D$30)-MAX('Cronograma (Gantt)'!$I26,D$28)+1)*'Cronograma (Gantt)'!$G26/'Cronograma (Gantt)'!$H26 | E34: =MAX(0,MIN('Cronograma (Gantt)'!$J26,E$30)-MAX('Cronograma (Gantt)'!$I26,E$28)+1)*'Cronograma (Gantt)'!$G26/'Cronograma (Gantt)'!$H26 | F34: =MAX(0,MIN('Cronograma (Gantt)'!$J26,F$30)-MAX('Cronograma (Gantt)'!$I26,F$28)+1)*'Cronograma (Gantt)'!$G26/'Cronograma (Gantt)'!$H26 | G34: =MAX(0,MIN('Cronograma (Gantt)'!$J26,G$30)-MAX('Cronograma (Gantt)'!$I26,G$28)+1)*'Cronograma (Gantt)'!$G26/'Cronograma (Gantt)'!$H26 | H34: =MAX(0,MIN('Cronograma (Gantt)'!$J26,H$30)-MAX('Cronograma (Gantt)'!$I26,H$28)+1)*'Cronograma (Gantt)'!$G26/'Cronograma (Gantt)'!$H26 | I34: =MAX(0,MIN('Cronograma (Gantt)'!$J26,I$30)-MAX('Cronograma (Gantt)'!$I26,I$28)+1)*'Cronograma (Gantt)'!$G26/'Cronograma (Gantt)'!$H26
A35: 27 | B35: ='Cronograma (Gantt)'!F27 | C35: =MAX(0,MIN('Cronograma (Gantt)'!$J27,C$30)-MAX('Cronograma (Gantt)'!$I27,C$28)+1)*'Cronograma (Gantt)'!$G27/'Cronograma (Gantt)'!$H27 | D35: =MAX(0,MIN('Cronograma (Gantt)'!$J27,D$30)-MAX('Cronograma (Gantt)'!$I27,D$28)+1)*'Cronograma (Gantt)'!$G27/'Cronograma (Gantt)'!$H27 | E35: =MAX(0,MIN('Cronograma (Gantt)'!$J27,E$30)-MAX('Cronograma (Gantt)'!$I27,E$28)+1)*'Cronograma (Gantt)'!$G27/'Cronograma (Gantt)'!$H27 | F35: =MAX(0,MIN('Cronograma (Gantt)'!$J27,F$30)-MAX('Cronograma (Gantt)'!$I27,F$28)+1)*'Cronograma (Gantt)'!$G27/'Cronograma (Gantt)'!$H27 | G35: =MAX(0,MIN('Cronograma (Gantt)'!$J27,G$30)-MAX('Cronograma (Gantt)'!$I27,G$28)+1)*'Cronograma (Gantt)'!$G27/'Cronograma (Gantt)'!$H27 | H35: =MAX(0,MIN('Cronograma (Gantt)'!$J27,H$30)-MAX('Cronograma (Gantt)'!$I27,H$28)+1)*'Cronograma (Gantt)'!$G27/'Cronograma (Gantt)'!$H27 | I35: =MAX(0,MIN('Cronograma (Gantt)'!$J27,I$30)-MAX('Cronograma (Gantt)'!$I27,I$28)+1)*'Cronograma (Gantt)'!$G27/'Cronograma (Gantt)'!$H27
A36: 29 | B36: ='Cronograma (Gantt)'!F29 | C36: =MAX(0,MIN('Cronograma (Gantt)'!$J29,C$30)-MAX('Cronograma (Gantt)'!$I29,C$28)+1)*'Cronograma (Gantt)'!$G29/'Cronograma (Gantt)'!$H29 | D36: =MAX(0,MIN('Cronograma (Gantt)'!$J29,D$30)-MAX('Cronograma (Gantt)'!$I29,D$28)+1)*'Cronograma (Gantt)'!$G29/'Cronograma (Gantt)'!$H29 | E36: =MAX(0,MIN('Cronograma (Gantt)'!$J29,E$30)-MAX('Cronograma (Gantt)'!$I29,E$28)+1)*'Cronograma (Gantt)'!$G29/'Cronograma (Gantt)'!$H29 | F36: =MAX(0,MIN('Cronograma (Gantt)'!$J29,F$30)-MAX('Cronograma (Gantt)'!$I29,F$28)+1)*'Cronograma (Gantt)'!$G29/'Cronograma (Gantt)'!$H29 | G36: =MAX(0,MIN('Cronograma (Gantt)'!$J29,G$30)-MAX('Cronograma (Gantt)'!$I29,G$28)+1)*'Cronograma (Gantt)'!$G29/'Cronograma (Gantt)'!$H29 | H36: =MAX(0,MIN('Cronograma (Gantt)'!$J29,H$30)-MAX('Cronograma (Gantt)'!$I29,H$28)+1)*'Cronograma (Gantt)'!$G29/'Cronograma (Gantt)'!$H29 | I36: =MAX(0,MIN('Cronograma (Gantt)'!$J29,I$30)-MAX('Cronograma (Gantt)'!$I29,I$28)+1)*'Cronograma (Gantt)'!$G29/'Cronograma (Gantt)'!$H29
A37: 30 | B37: ='Cronograma (Gantt)'!F30 | C37: =MAX(0,MIN('Cronograma (Gantt)'!$J30,C$30)-MAX('Cronograma (Gantt)'!$I30,C$28)+1)*'Cronograma (Gantt)'!$G30/'Cronograma (Gantt)'!$H30 | D37: =MAX(0,MIN('Cronograma (Gantt)'!$J30,D$30)-MAX('Cronograma (Gantt)'!$I30,D$28)+1)*'Cronograma (Gantt)'!$G30/'Cronograma (Gantt)'!$H30 | E37: =MAX(0,MIN('Cronograma (Gantt)'!$J30,E$30)-MAX('Cronograma (Gantt)'!$I30,E$28)+1)*'Cronograma (Gantt)'!$G30/'Cronograma (Gantt)'!$H30 | F37: =MAX(0,MIN('Cronograma (Gantt)'!$J30,F$30)-MAX('Cronograma (Gantt)'!$I30,F$28)+1)*'Cronograma (Gantt)'!$G30/'Cronograma (Gantt)'!$H30 | G37: =MAX(0,MIN('Cronograma (Gantt)'!$J30,G$30)-MAX('Cronograma (Gantt)'!$I30,G$28)+1)*'Cronograma (Gantt)'!$G30/'Cronograma (Gantt)'!$H30 | H37: =MAX(0,MIN('Cronograma (Gantt)'!$J30,H$30)-MAX('Cronograma (Gantt)'!$I30,H$28)+1)*'Cronograma (Gantt)'!$G30/'Cronograma (Gantt)'!$H30 | I37: =MAX(0,MIN('Cronograma (Gantt)'!$J30,I$30)-MAX('Cronograma (Gantt)'!$I30,I$28)+1)*'Cronograma (Gantt)'!$G30/'Cronograma (Gantt)'!$H30
A38: 31 | B38: ='Cronograma (Gantt)'!F31 | C38: =MAX(0,MIN('Cronograma (Gantt)'!$J31,C$30)-MAX('Cronograma (Gantt)'!$I31,C$28)+1)*'Cronograma (Gantt)'!$G31/'Cronograma (Gantt)'!$H31 | D38: =MAX(0,MIN('Cronograma (Gantt)'!$J31,D$30)-MAX('Cronograma (Gantt)'!$I31,D$28)+1)*'Cronograma (Gantt)'!$G31/'Cronograma (Gantt)'!$H31 | E38: =MAX(0,MIN('Cronograma (Gantt)'!$J31,E$30)-MAX('Cronograma (Gantt)'!$I31,E$28)+1)*'Cronograma (Gantt)'!$G31/'Cronograma (Gantt)'!$H31 | F38: =MAX(0,MIN('Cronograma (Gantt)'!$J31,F$30)-MAX('Cronograma (Gantt)'!$I31,F$28)+1)*'Cronograma (Gantt)'!$G31/'Cronograma (Gantt)'!$H31 | G38: =MAX(0,MIN('Cronograma (Gantt)'!$J31,G$30)-MAX('Cronograma (Gantt)'!$I31,G$28)+1)*'Cronograma (Gantt)'!$G31/'Cronograma (Gantt)'!$H31 | H38: =MAX(0,MIN('Cronograma (Gantt)'!$J31,H$30)-MAX('Cronograma (Gantt)'!$I31,H$28)+1)*'Cronograma (Gantt)'!$G31/'Cronograma (Gantt)'!$H31 | I38: =MAX(0,MIN('Cronograma (Gantt)'!$J31,I$30)-MAX('Cronograma (Gantt)'!$I31,I$28)+1)*'Cronograma (Gantt)'!$G31/'Cronograma (Gantt)'!$H31
A39: 32 | B39: ='Cronograma (Gantt)'!F32 | C39: =MAX(0,MIN('Cronograma (Gantt)'!$J32,C$30)-MAX('Cronograma (Gantt)'!$I32,C$28)+1)*'Cronograma (Gantt)'!$G32/'Cronograma (Gantt)'!$H32 | D39: =MAX(0,MIN('Cronograma (Gantt)'!$J32,D$30)-MAX('Cronograma (Gantt)'!$I32,D$28)+1)*'Cronograma (Gantt)'!$G32/'Cronograma (Gantt)'!$H32 | E39: =MAX(0,MIN('Cronograma (Gantt)'!$J32,E$30)-MAX('Cronograma (Gantt)'!$I32,E$28)+1)*'Cronograma (Gantt)'!$G32/'Cronograma (Gantt)'!$H32 | F39: =MAX(0,MIN('Cronograma (Gantt)'!$J32,F$30)-MAX('Cronograma (Gantt)'!$I32,F$28)+1)*'Cronograma (Gantt)'!$G32/'Cronograma (Gantt)'!$H32 | G39: =MAX(0,MIN('Cronograma (Gantt)'!$J32,G$30)-MAX('Cronograma (Gantt)'!$I32,G$28)+1)*'Cronograma (Gantt)'!$G32/'Cronograma (Gantt)'!$H32 | H39: =MAX(0,MIN('Cronograma (Gantt)'!$J32,H$30)-MAX('Cronograma (Gantt)'!$I32,H$28)+1)*'Cronograma (Gantt)'!$G32/'Cronograma (Gantt)'!$H32 | I39: =MAX(0,MIN('Cronograma (Gantt)'!$J32,I$30)-MAX('Cronograma (Gantt)'!$I32,I$28)+1)*'Cronograma (Gantt)'!$G32/'Cronograma (Gantt)'!$H32
A40: 33 | B40: ='Cronograma (Gantt)'!F33 | C40: =MAX(0,MIN('Cronograma (Gantt)'!$J33,C$30)-MAX('Cronograma (Gantt)'!$I33,C$28)+1)*'Cronograma (Gantt)'!$G33/'Cronograma (Gantt)'!$H33 | D40: =MAX(0,MIN('Cronograma (Gantt)'!$J33,D$30)-MAX('Cronograma (Gantt)'!$I33,D$28)+1)*'Cronograma (Gantt)'!$G33/'Cronograma (Gantt)'!$H33 | E40: =MAX(0,MIN('Cronograma (Gantt)'!$J33,E$30)-MAX('Cronograma (Gantt)'!$I33,E$28)+1)*'Cronograma (Gantt)'!$G33/'Cronograma (Gantt)'!$H33 | F40: =MAX(0,MIN('Cronograma (Gantt)'!$J33,F$30)-MAX('Cronograma (Gantt)'!$I33,F$28)+1)*'Cronograma (Gantt)'!$G33/'Cronograma (Gantt)'!$H33 | G40: =MAX(0,MIN('Cronograma (Gantt)'!$J33,G$30)-MAX('Cronograma (Gantt)'!$I33,G$28)+1)*'Cronograma (Gantt)'!$G33/'Cronograma (Gantt)'!$H33 | H40: =MAX(0,MIN('Cronograma (Gantt)'!$J33,H$30)-MAX('Cronograma (Gantt)'!$I33,H$28)+1)*'Cronograma (Gantt)'!$G33/'Cronograma (Gantt)'!$H33 | I40: =MAX(0,MIN('Cronograma (Gantt)'!$J33,I$30)-MAX('Cronograma (Gantt)'!$I33,I$28)+1)*'Cronograma (Gantt)'!$G33/'Cronograma (Gantt)'!$H33
A41: 34 | B41: ='Cronograma (Gantt)'!F34 | C41: =MAX(0,MIN('Cronograma (Gantt)'!$J34,C$30)-MAX('Cronograma (Gantt)'!$I34,C$28)+1)*'Cronograma (Gantt)'!$G34/'Cronograma (Gantt)'!$H34 | D41: =MAX(0,MIN('Cronograma (Gantt)'!$J34,D$30)-MAX('Cronograma (Gantt)'!$I34,D$28)+1)*'Cronograma (Gantt)'!$G34/'Cronograma (Gantt)'!$H34 | E41: =MAX(0,MIN('Cronograma (Gantt)'!$J34,E$30)-MAX('Cronograma (Gantt)'!$I34,E$28)+1)*'Cronograma (Gantt)'!$G34/'Cronograma (Gantt)'!$H34 | F41: =MAX(0,MIN('Cronograma (Gantt)'!$J34,F$30)-MAX('Cronograma (Gantt)'!$I34,F$28)+1)*'Cronograma (Gantt)'!$G34/'Cronograma (Gantt)'!$H34 | G41: =MAX(0,MIN('Cronograma (Gantt)'!$J34,G$30)-MAX('Cronograma (Gantt)'!$I34,G$28)+1)*'Cronograma (Gantt)'!$G34/'Cronograma (Gantt)'!$H34 | H41: =MAX(0,MIN('Cronograma (Gantt)'!$J34,H$30)-MAX('Cronograma (Gantt)'!$I34,H$28)+1)*'Cronograma (Gantt)'!$G34/'Cronograma (Gantt)'!$H34 | I41: =MAX(0,MIN('Cronograma (Gantt)'!$J34,I$30)-MAX('Cronograma (Gantt)'!$I34,I$28)+1)*'Cronograma (Gantt)'!$G34/'Cronograma (Gantt)'!$H34
A42: 36 | B42: ='Cronograma (Gantt)'!F36 | C42: =MAX(0,MIN('Cronograma (Gantt)'!$J36,C$30)-MAX('Cronograma (Gantt)'!$I36,C$28)+1)*'Cronograma (Gantt)'!$G36/'Cronograma (Gantt)'!$H36 | D42: =MAX(0,MIN('Cronograma (Gantt)'!$J36,D$30)-MAX('Cronograma (Gantt)'!$I36,D$28)+1)*'Cronograma (Gantt)'!$G36/'Cronograma (Gantt)'!$H36 | E42: =MAX(0,MIN('Cronograma (Gantt)'!$J36,E$30)-MAX('Cronograma (Gantt)'!$I36,E$28)+1)*'Cronograma (Gantt)'!$G36/'Cronograma (Gantt)'!$H36 | F42: =MAX(0,MIN('Cronograma (Gantt)'!$J36,F$30)-MAX('Cronograma (Gantt)'!$I36,F$28)+1)*'Cronograma (Gantt)'!$G36/'Cronograma (Gantt)'!$H36 | G42: =MAX(0,MIN('Cronograma (Gantt)'!$J36,G$30)-MAX('Cronograma (Gantt)'!$I36,G$28)+1)*'Cronograma (Gantt)'!$G36/'Cronograma (Gantt)'!$H36 | H42: =MAX(0,MIN('Cronograma (Gantt)'!$J36,H$30)-MAX('Cronograma (Gantt)'!$I36,H$28)+1)*'Cronograma (Gantt)'!$G36/'Cronograma (Gantt)'!$H36 | I42: =MAX(0,MIN('Cronograma (Gantt)'!$J36,I$30)-MAX('Cronograma (Gantt)'!$I36,I$28)+1)*'Cronograma (Gantt)'!$G36/'Cronograma (Gantt)'!$H36
A43: 37 | B43: ='Cronograma (Gantt)'!F37 | C43: =MAX(0,MIN('Cronograma (Gantt)'!$J37,C$30)-MAX('Cronograma (Gantt)'!$I37,C$28)+1)*'Cronograma (Gantt)'!$G37/'Cronograma (Gantt)'!$H37 | D43: =MAX(0,MIN('Cronograma (Gantt)'!$J37,D$30)-MAX('Cronograma (Gantt)'!$I37,D$28)+1)*'Cronograma (Gantt)'!$G37/'Cronograma (Gantt)'!$H37 | E43: =MAX(0,MIN('Cronograma (Gantt)'!$J37,E$30)-MAX('Cronograma (Gantt)'!$I37,E$28)+1)*'Cronograma (Gantt)'!$G37/'Cronograma (Gantt)'!$H37 | F43: =MAX(0,MIN('Cronograma (Gantt)'!$J37,F$30)-MAX('Cronograma (Gantt)'!$I37,F$28)+1)*'Cronograma (Gantt)'!$G37/'Cronograma (Gantt)'!$H37 | G43: =MAX(0,MIN('Cronograma (Gantt)'!$J37,G$30)-MAX('Cronograma (Gantt)'!$I37,G$28)+1)*'Cronograma (Gantt)'!$G37/'Cronograma (Gantt)'!$H37 | H43: =MAX(0,MIN('Cronograma (Gantt)'!$J37,H$30)-MAX('Cronograma (Gantt)'!$I37,H$28)+1)*'Cronograma (Gantt)'!$G37/'Cronograma (Gantt)'!$H37 | I43: =MAX(0,MIN('Cronograma (Gantt)'!$J37,I$30)-MAX('Cronograma (Gantt)'!$I37,I$28)+1)*'Cronograma (Gantt)'!$G37/'Cronograma (Gantt)'!$H37
A44: 39 | B44: ='Cronograma (Gantt)'!F39 | C44: =MAX(0,MIN('Cronograma (Gantt)'!$J39,C$30)-MAX('Cronograma (Gantt)'!$I39,C$28)+1)*'Cronograma (Gantt)'!$G39/'Cronograma (Gantt)'!$H39 | D44: =MAX(0,MIN('Cronograma (Gantt)'!$J39,D$30)-MAX('Cronograma (Gantt)'!$I39,D$28)+1)*'Cronograma (Gantt)'!$G39/'Cronograma (Gantt)'!$H39 | E44: =MAX(0,MIN('Cronograma (Gantt)'!$J39,E$30)-MAX('Cronograma (Gantt)'!$I39,E$28)+1)*'Cronograma (Gantt)'!$G39/'Cronograma (Gantt)'!$H39 | F44: =MAX(0,MIN('Cronograma (Gantt)'!$J39,F$30)-MAX('Cronograma (Gantt)'!$I39,F$28)+1)*'Cronograma (Gantt)'!$G39/'Cronograma (Gantt)'!$H39 | G44: =MAX(0,MIN('Cronograma (Gantt)'!$J39,G$30)-MAX('Cronograma (Gantt)'!$I39,G$28)+1)*'Cronograma (Gantt)'!$G39/'Cronograma (Gantt)'!$H39 | H44: =MAX(0,MIN('Cronograma (Gantt)'!$J39,H$30)-MAX('Cronograma (Gantt)'!$I39,H$28)+1)*'Cronograma (Gantt)'!$G39/'Cronograma (Gantt)'!$H39 | I44: =MAX(0,MIN('Cronograma (Gantt)'!$J39,I$30)-MAX('Cronograma (Gantt)'!$I39,I$28)+1)*'Cronograma (Gantt)'!$G39/'Cronograma (Gantt)'!$H39
A45: 40 | B45: ='Cronograma (Gantt)'!F40 | C45: =MAX(0,MIN('Cronograma (Gantt)'!$J40,C$30)-MAX('Cronograma (Gantt)'!$I40,C$28)+1)*'Cronograma (Gantt)'!$G40/'Cronograma (Gantt)'!$H40 | D45: =MAX(0,MIN('Cronograma (Gantt)'!$J40,D$30)-MAX('Cronograma (Gantt)'!$I40,D$28)+1)*'Cronograma (Gantt)'!$G40/'Cronograma (Gantt)'!$H40 | E45: =MAX(0,MIN('Cronograma (Gantt)'!$J40,E$30)-MAX('Cronograma (Gantt)'!$I40,E$28)+1)*'Cronograma (Gantt)'!$G40/'Cronograma (Gantt)'!$H40 | F45: =MAX(0,MIN('Cronograma (Gantt)'!$J40,F$30)-MAX('Cronograma (Gantt)'!$I40,F$28)+1)*'Cronograma (Gantt)'!$G40/'Cronograma (Gantt)'!$H40 | G45: =MAX(0,MIN('Cronograma (Gantt)'!$J40,G$30)-MAX('Cronograma (Gantt)'!$I40,G$28)+1)*'Cronograma (Gantt)'!$G40/'Cronograma (Gantt)'!$H40 | H45: =MAX(0,MIN('Cronograma (Gantt)'!$J40,H$30)-MAX('Cronograma (Gantt)'!$I40,H$28)+1)*'Cronograma (Gantt)'!$G40/'Cronograma (Gantt)'!$H40 | I45: =MAX(0,MIN('Cronograma (Gantt)'!$J40,I$30)-MAX('Cronograma (Gantt)'!$I40,I$28)+1)*'Cronograma (Gantt)'!$G40/'Cronograma (Gantt)'!$H40
A46: 41 | B46: ='Cronograma (Gantt)'!F41 | C46: =MAX(0,MIN('Cronograma (Gantt)'!$J41,C$30)-MAX('Cronograma (Gantt)'!$I41,C$28)+1)*'Cronograma (Gantt)'!$G41/'Cronograma (Gantt)'!$H41 | D46: =MAX(0,MIN('Cronograma (Gantt)'!$J41,D$30)-MAX('Cronograma (Gantt)'!$I41,D$28)+1)*'Cronograma (Gantt)'!$G41/'Cronograma (Gantt)'!$H41 | E46: =MAX(0,MIN('Cronograma (Gantt)'!$J41,E$30)-MAX('Cronograma (Gantt)'!$I41,E$28)+1)*'Cronograma (Gantt)'!$G41/'Cronograma (Gantt)'!$H41 | F46: =MAX(0,MIN('Cronograma (Gantt)'!$J41,F$30)-MAX('Cronograma (Gantt)'!$I41,F$28)+1)*'Cronograma (Gantt)'!$G41/'Cronograma (Gantt)'!$H41 | G46: =MAX(0,MIN('Cronograma (Gantt)'!$J41,G$30)-MAX('Cronograma (Gantt)'!$I41,G$28)+1)*'Cronograma (Gantt)'!$G41/'Cronograma (Gantt)'!$H41 | H46: =MAX(0,MIN('Cronograma (Gantt)'!$J41,H$30)-MAX('Cronograma (Gantt)'!$I41,H$28)+1)*'Cronograma (Gantt)'!$G41/'Cronograma (Gantt)'!$H41 | I46: =MAX(0,MIN('Cronograma (Gantt)'!$J41,I$30)-MAX('Cronograma (Gantt)'!$I41,I$28)+1)*'Cronograma (Gantt)'!$G41/'Cronograma (Gantt)'!$H41
A47: 42 | B47: ='Cronograma (Gantt)'!F42 | C47: =MAX(0,MIN('Cronograma (Gantt)'!$J42,C$30)-MAX('Cronograma (Gantt)'!$I42,C$28)+1)*'Cronograma (Gantt)'!$G42/'Cronograma (Gantt)'!$H42 | D47: =MAX(0,MIN('Cronograma (Gantt)'!$J42,D$30)-MAX('Cronograma (Gantt)'!$I42,D$28)+1)*'Cronograma (Gantt)'!$G42/'Cronograma (Gantt)'!$H42 | E47: =MAX(0,MIN('Cronograma (Gantt)'!$J42,E$30)-MAX('Cronograma (Gantt)'!$I42,E$28)+1)*'Cronograma (Gantt)'!$G42/'Cronograma (Gantt)'!$H42 | F47: =MAX(0,MIN('Cronograma (Gantt)'!$J42,F$30)-MAX('Cronograma (Gantt)'!$I42,F$28)+1)*'Cronograma (Gantt)'!$G42/'Cronograma (Gantt)'!$H42 | G47: =MAX(0,MIN('Cronograma (Gantt)'!$J42,G$30)-MAX('Cronograma (Gantt)'!$I42,G$28)+1)*'Cronograma (Gantt)'!$G42/'Cronograma (Gantt)'!$H42 | H47: =MAX(0,MIN('Cronograma (Gantt)'!$J42,H$30)-MAX('Cronograma (Gantt)'!$I42,H$28)+1)*'Cronograma (Gantt)'!$G42/'Cronograma (Gantt)'!$H42 | I47: =MAX(0,MIN('Cronograma (Gantt)'!$J42,I$30)-MAX('Cronograma (Gantt)'!$I42,I$28)+1)*'Cronograma (Gantt)'!$G42/'Cronograma (Gantt)'!$H42
A48: 43 | B48: ='Cronograma (Gantt)'!F43 | C48: =MAX(0,MIN('Cronograma (Gantt)'!$J43,C$30)-MAX('Cronograma (Gantt)'!$I43,C$28)+1)*'Cronograma (Gantt)'!$G43/'Cronograma (Gantt)'!$H43 | D48: =MAX(0,MIN('Cronograma (Gantt)'!$J43,D$30)-MAX('Cronograma (Gantt)'!$I43,D$28)+1)*'Cronograma (Gantt)'!$G43/'Cronograma (Gantt)'!$H43 | E48: =MAX(0,MIN('Cronograma (Gantt)'!$J43,E$30)-MAX('Cronograma (Gantt)'!$I43,E$28)+1)*'Cronograma (Gantt)'!$G43/'Cronograma (Gantt)'!$H43 | F48: =MAX(0,MIN('Cronograma (Gantt)'!$J43,F$30)-MAX('Cronograma (Gantt)'!$I43,F$28)+1)*'Cronograma (Gantt)'!$G43/'Cronograma (Gantt)'!$H43 | G48: =MAX(0,MIN('Cronograma (Gantt)'!$J43,G$30)-MAX('Cronograma (Gantt)'!$I43,G$28)+1)*'Cronograma (Gantt)'!$G43/'Cronograma (Gantt)'!$H43 | H48: =MAX(0,MIN('Cronograma (Gantt)'!$J43,H$30)-MAX('Cronograma (Gantt)'!$I43,H$28)+1)*'Cronograma (Gantt)'!$G43/'Cronograma (Gantt)'!$H43 | I48: =MAX(0,MIN('Cronograma (Gantt)'!$J43,I$30)-MAX('Cronograma (Gantt)'!$I43,I$28)+1)*'Cronograma (Gantt)'!$G43/'Cronograma (Gantt)'!$H43
A49: 45 | B49: ='Cronograma (Gantt)'!F45 | C49: =MAX(0,MIN('Cronograma (Gantt)'!$J45,C$30)-MAX('Cronograma (Gantt)'!$I45,C$28)+1)*'Cronograma (Gantt)'!$G45/'Cronograma (Gantt)'!$H45 | D49: =MAX(0,MIN('Cronograma (Gantt)'!$J45,D$30)-MAX('Cronograma (Gantt)'!$I45,D$28)+1)*'Cronograma (Gantt)'!$G45/'Cronograma (Gantt)'!$H45 | E49: =MAX(0,MIN('Cronograma (Gantt)'!$J45,E$30)-MAX('Cronograma (Gantt)'!$I45,E$28)+1)*'Cronograma (Gantt)'!$G45/'Cronograma (Gantt)'!$H45 | F49: =MAX(0,MIN('Cronograma (Gantt)'!$J45,F$30)-MAX('Cronograma (Gantt)'!$I45,F$28)+1)*'Cronograma (Gantt)'!$G45/'Cronograma (Gantt)'!$H45 | G49: =MAX(0,MIN('Cronograma (Gantt)'!$J45,G$30)-MAX('Cronograma (Gantt)'!$I45,G$28)+1)*'Cronograma (Gantt)'!$G45/'Cronograma (Gantt)'!$H45 | H49: =MAX(0,MIN('Cronograma (Gantt)'!$J45,H$30)-MAX('Cronograma (Gantt)'!$I45,H$28)+1)*'Cronograma (Gantt)'!$G45/'Cronograma (Gantt)'!$H45 | I49: =MAX(0,MIN('Cronograma (Gantt)'!$J45,I$30)-MAX('Cronograma (Gantt)'!$I45,I$28)+1)*'Cronograma (Gantt)'!$G45/'Cronograma (Gantt)'!$H45
A50: 46 | B50: ='Cronograma (Gantt)'!F46 | C50: =MAX(0,MIN('Cronograma (Gantt)'!$J46,C$30)-MAX('Cronograma (Gantt)'!$I46,C$28)+1)*'Cronograma (Gantt)'!$G46/'Cronograma (Gantt)'!$H46 | D50: =MAX(0,MIN('Cronograma (Gantt)'!$J46,D$30)-MAX('Cronograma (Gantt)'!$I46,D$28)+1)*'Cronograma (Gantt)'!$G46/'Cronograma (Gantt)'!$H46 | E50: =MAX(0,MIN('Cronograma (Gantt)'!$J46,E$30)-MAX('Cronograma (Gantt)'!$I46,E$28)+1)*'Cronograma (Gantt)'!$G46/'Cronograma (Gantt)'!$H46 | F50: =MAX(0,MIN('Cronograma (Gantt)'!$J46,F$30)-MAX('Cronograma (Gantt)'!$I46,F$28)+1)*'Cronograma (Gantt)'!$G46/'Cronograma (Gantt)'!$H46 | G50: =MAX(0,MIN('Cronograma (Gantt)'!$J46,G$30)-MAX('Cronograma (Gantt)'!$I46,G$28)+1)*'Cronograma (Gantt)'!$G46/'Cronograma (Gantt)'!$H46 | H50: =MAX(0,MIN('Cronograma (Gantt)'!$J46,H$30)-MAX('Cronograma (Gantt)'!$I46,H$28)+1)*'Cronograma (Gantt)'!$G46/'Cronograma (Gantt)'!$H46 | I50: =MAX(0,MIN('Cronograma (Gantt)'!$J46,I$30)-MAX('Cronograma (Gantt)'!$I46,I$28)+1)*'Cronograma (Gantt)'!$G46/'Cronograma (Gantt)'!$H46
A51: 47 | B51: ='Cronograma (Gantt)'!F47 | C51: =MAX(0,MIN('Cronograma (Gantt)'!$J47,C$30)-MAX('Cronograma (Gantt)'!$I47,C$28)+1)*'Cronograma (Gantt)'!$G47/'Cronograma (Gantt)'!$H47 | D51: =MAX(0,MIN('Cronograma (Gantt)'!$J47,D$30)-MAX('Cronograma (Gantt)'!$I47,D$28)+1)*'Cronograma (Gantt)'!$G47/'Cronograma (Gantt)'!$H47 | E51: =MAX(0,MIN('Cronograma (Gantt)'!$J47,E$30)-MAX('Cronograma (Gantt)'!$I47,E$28)+1)*'Cronograma (Gantt)'!$G47/'Cronograma (Gantt)'!$H47 | F51: =MAX(0,MIN('Cronograma (Gantt)'!$J47,F$30)-MAX('Cronograma (Gantt)'!$I47,F$28)+1)*'Cronograma (Gantt)'!$G47/'Cronograma (Gantt)'!$H47 | G51: =MAX(0,MIN('Cronograma (Gantt)'!$J47,G$30)-MAX('Cronograma (Gantt)'!$I47,G$28)+1)*'Cronograma (Gantt)'!$G47/'Cronograma (Gantt)'!$H47 | H51: =MAX(0,MIN('Cronograma (Gantt)'!$J47,H$30)-MAX('Cronograma (Gantt)'!$I47,H$28)+1)*'Cronograma (Gantt)'!$G47/'Cronograma (Gantt)'!$H47 | I51: =MAX(0,MIN('Cronograma (Gantt)'!$J47,I$30)-MAX('Cronograma (Gantt)'!$I47,I$28)+1)*'Cronograma (Gantt)'!$G47/'Cronograma (Gantt)'!$H47
A52: 48 | B52: ='Cronograma (Gantt)'!F48 | C52: =MAX(0,MIN('Cronograma (Gantt)'!$J48,C$30)-MAX('Cronograma (Gantt)'!$I48,C$28)+1)*'Cronograma (Gantt)'!$G48/'Cronograma (Gantt)'!$H48 | D52: =MAX(0,MIN('Cronograma (Gantt)'!$J48,D$30)-MAX('Cronograma (Gantt)'!$I48,D$28)+1)*'Cronograma (Gantt)'!$G48/'Cronograma (Gantt)'!$H48 | E52: =MAX(0,MIN('Cronograma (Gantt)'!$J48,E$30)-MAX('Cronograma (Gantt)'!$I48,E$28)+1)*'Cronograma (Gantt)'!$G48/'Cronograma (Gantt)'!$H48 | F52: =MAX(0,MIN('Cronograma (Gantt)'!$J48,F$30)-MAX('Cronograma (Gantt)'!$I48,F$28)+1)*'Cronograma (Gantt)'!$G48/'Cronograma (Gantt)'!$H48 | G52: =MAX(0,MIN('Cronograma (Gantt)'!$J48,G$30)-MAX('Cronograma (Gantt)'!$I48,G$28)+1)*'Cronograma (Gantt)'!$G48/'Cronograma (Gantt)'!$H48 | H52: =MAX(0,MIN('Cronograma (Gantt)'!$J48,H$30)-MAX('Cronograma (Gantt)'!$I48,H$28)+1)*'Cronograma (Gantt)'!$G48/'Cronograma (Gantt)'!$H48 | I52: =MAX(0,MIN('Cronograma (Gantt)'!$J48,I$30)-MAX('Cronograma (Gantt)'!$I48,I$28)+1)*'Cronograma (Gantt)'!$G48/'Cronograma (Gantt)'!$H48
A53: 49 | B53: ='Cronograma (Gantt)'!F49 | C53: =MAX(0,MIN('Cronograma (Gantt)'!$J49,C$30)-MAX('Cronograma (Gantt)'!$I49,C$28)+1)*'Cronograma (Gantt)'!$G49/'Cronograma (Gantt)'!$H49 | D53: =MAX(0,MIN('Cronograma (Gantt)'!$J49,D$30)-MAX('Cronograma (Gantt)'!$I49,D$28)+1)*'Cronograma (Gantt)'!$G49/'Cronograma (Gantt)'!$H49 | E53: =MAX(0,MIN('Cronograma (Gantt)'!$J49,E$30)-MAX('Cronograma (Gantt)'!$I49,E$28)+1)*'Cronograma (Gantt)'!$G49/'Cronograma (Gantt)'!$H49 | F53: =MAX(0,MIN('Cronograma (Gantt)'!$J49,F$30)-MAX('Cronograma (Gantt)'!$I49,F$28)+1)*'Cronograma (Gantt)'!$G49/'Cronograma (Gantt)'!$H49 | G53: =MAX(0,MIN('Cronograma (Gantt)'!$J49,G$30)-MAX('Cronograma (Gantt)'!$I49,G$28)+1)*'Cronograma (Gantt)'!$G49/'Cronograma (Gantt)'!$H49 | H53: =MAX(0,MIN('Cronograma (Gantt)'!$J49,H$30)-MAX('Cronograma (Gantt)'!$I49,H$28)+1)*'Cronograma (Gantt)'!$G49/'Cronograma (Gantt)'!$H49 | I53: =MAX(0,MIN('Cronograma (Gantt)'!$J49,I$30)-MAX('Cronograma (Gantt)'!$I49,I$28)+1)*'Cronograma (Gantt)'!$G49/'Cronograma (Gantt)'!$H49
A54: 50 | B54: ='Cronograma (Gantt)'!F50 | C54: =MAX(0,MIN('Cronograma (Gantt)'!$J50,C$30)-MAX('Cronograma (Gantt)'!$I50,C$28)+1)*'Cronograma (Gantt)'!$G50/'Cronograma (Gantt)'!$H50 | D54: =MAX(0,MIN('Cronograma (Gantt)'!$J50,D$30)-MAX('Cronograma (Gantt)'!$I50,D$28)+1)*'Cronograma (Gantt)'!$G50/'Cronograma (Gantt)'!$H50 | E54: =MAX(0,MIN('Cronograma (Gantt)'!$J50,E$30)-MAX('Cronograma (Gantt)'!$I50,E$28)+1)*'Cronograma (Gantt)'!$G50/'Cronograma (Gantt)'!$H50 | F54: =MAX(0,MIN('Cronograma (Gantt)'!$J50,F$30)-MAX('Cronograma (Gantt)'!$I50,F$28)+1)*'Cronograma (Gantt)'!$G50/'Cronograma (Gantt)'!$H50 | G54: =MAX(0,MIN('Cronograma (Gantt)'!$J50,G$30)-MAX('Cronograma (Gantt)'!$I50,G$28)+1)*'Cronograma (Gantt)'!$G50/'Cronograma (Gantt)'!$H50 | H54: =MAX(0,MIN('Cronograma (Gantt)'!$J50,H$30)-MAX('Cronograma (Gantt)'!$I50,H$28)+1)*'Cronograma (Gantt)'!$G50/'Cronograma (Gantt)'!$H50 | I54: =MAX(0,MIN('Cronograma (Gantt)'!$J50,I$30)-MAX('Cronograma (Gantt)'!$I50,I$28)+1)*'Cronograma (Gantt)'!$G50/'Cronograma (Gantt)'!$H50
A55: 51 | B55: ='Cronograma (Gantt)'!F51 | C55: =MAX(0,MIN('Cronograma (Gantt)'!$J51,C$30)-MAX('Cronograma (Gantt)'!$I51,C$28)+1)*'Cronograma (Gantt)'!$G51/'Cronograma (Gantt)'!$H51 | D55: =MAX(0,MIN('Cronograma (Gantt)'!$J51,D$30)-MAX('Cronograma (Gantt)'!$I51,D$28)+1)*'Cronograma (Gantt)'!$G51/'Cronograma (Gantt)'!$H51 | E55: =MAX(0,MIN('Cronograma (Gantt)'!$J51,E$30)-MAX('Cronograma (Gantt)'!$I51,E$28)+1)*'Cronograma (Gantt)'!$G51/'Cronograma (Gantt)'!$H51 | F55: =MAX(0,MIN('Cronograma (Gantt)'!$J51,F$30)-MAX('Cronograma (Gantt)'!$I51,F$28)+1)*'Cronograma (Gantt)'!$G51/'Cronograma (Gantt)'!$H51 | G55: =MAX(0,MIN('Cronograma (Gantt)'!$J51,G$30)-MAX('Cronograma (Gantt)'!$I51,G$28)+1)*'Cronograma (Gantt)'!$G51/'Cronograma (Gantt)'!$H51 | H55: =MAX(0,MIN('Cronograma (Gantt)'!$J51,H$30)-MAX('Cronograma (Gantt)'!$I51,H$28)+1)*'Cronograma (Gantt)'!$G51/'Cronograma (Gantt)'!$H51 | I55: =MAX(0,MIN('Cronograma (Gantt)'!$J51,I$30)-MAX('Cronograma (Gantt)'!$I51,I$28)+1)*'Cronograma (Gantt)'!$G51/'Cronograma (Gantt)'!$H51
A56: 52 | B56: ='Cronograma (Gantt)'!F52 | C56: =MAX(0,MIN('Cronograma (Gantt)'!$J52,C$30)-MAX('Cronograma (Gantt)'!$I52,C$28)+1)*'Cronograma (Gantt)'!$G52/'Cronograma (Gantt)'!$H52 | D56: =MAX(0,MIN('Cronograma (Gantt)'!$J52,D$30)-MAX('Cronograma (Gantt)'!$I52,D$28)+1)*'Cronograma (Gantt)'!$G52/'Cronograma (Gantt)'!$H52 | E56: =MAX(0,MIN('Cronograma (Gantt)'!$J52,E$30)-MAX('Cronograma (Gantt)'!$I52,E$28)+1)*'Cronograma (Gantt)'!$G52/'Cronograma (Gantt)'!$H52 | F56: =MAX(0,MIN('Cronograma (Gantt)'!$J52,F$30)-MAX('Cronograma (Gantt)'!$I52,F$28)+1)*'Cronograma (Gantt)'!$G52/'Cronograma (Gantt)'!$H52 | G56: =MAX(0,MIN('Cronograma (Gantt)'!$J52,G$30)-MAX('Cronograma (Gantt)'!$I52,G$28)+1)*'Cronograma (Gantt)'!$G52/'Cronograma (Gantt)'!$H52 | H56: =MAX(0,MIN('Cronograma (Gantt)'!$J52,H$30)-MAX('Cronograma (Gantt)'!$I52,H$28)+1)*'Cronograma (Gantt)'!$G52/'Cronograma (Gantt)'!$H52 | I56: =MAX(0,MIN('Cronograma (Gantt)'!$J52,I$30)-MAX('Cronograma (Gantt)'!$I52,I$28)+1)*'Cronograma (Gantt)'!$G52/'Cronograma (Gantt)'!$H52
...

Sheet Reserva y supuestos
A1: Supuestos del cronograma y reserva
A3: Calendario | B3: 7 días por semana (el equipo también trabaja fines de semana). Fechas de entrega del curso: domingos a las 23:59.
A4: Dedicación | B4: 3 horas por persona y día (≈ 21 h/semana) durante diseño, construcción y pruebas. Es mayor que las 8 h/semana supuestas en el Acta: ver el Plan de Gestión del Cronograma.
A5: Duración | B5: Duración (días) = esfuerzo estimado ÷ (3 h/día), redondeado hacia arriba. El esfuerzo proviene de la Plantilla MoSCoW v1.3.
A6: Dependencias | B6: Fin a inicio (FS). Además, una persona no ejecuta dos actividades a la vez (programación con recursos).
A7: Ciclos TSP | B7: Ciclo 1: hasta el 25/10 (v0.5). Ciclo 2: hasta el 15/11 (v0.9). Ciclo 3: hasta el 22/11. Cierre: 23/11–29/11 (v1.0).
A8: Fecha final | B8: Se asume el 29/11/2026 como fecha de entrega final del curso (por confirmar con el docente).
A9: Holgura | B9: Las actividades de cierre terminan el 26/11: quedan 3 días de holgura antes del hito final.
A11: Reserva (requisitos Could): no se programan en la línea base; se ejecutan solo si hay capacidad al final del ciclo 3.
A12: ID | B12: EDT | C12: Actividad | D12: Esfuerzo (h) | E12: Responsable
A13: 4107 | B13: 4.1.7 | C13: Simular la insuflación y la deformación de paredes (RF-03.7) | D13: 16 | E13: Cristian Cruz
A14: 4303 | B14: 4.3.3 | C14: Generar el mapa de calor Grad-CAM (RF-06.3) | D14: 8 | E14: Diego Agudelo
A15: 4211 | B15: 4.2.11 | C15: Implementar el reporte de caso incorrecto (RF-14.7) | D15: 3 | E15: Emmanuel Ospina
A16: 4508 | B16: 4.5.8 | C16: Desarrollar la tabla de clasificación (RF-16) | D16: 6 | E16: Diego Agudelo
